Traceback (most recent call last):
  File "/home/auralius/miniconda3/envs/py.3.12.4/lib/python3.12/site-packages/jupyter_cache/executors/utils.py", line 58, in single_nb_execution
    executenb(
  File "/home/auralius/miniconda3/envs/py.3.12.4/lib/python3.12/site-packages/nbclient/client.py", line 1319, in execute
    return NotebookClient(nb=nb, resources=resources, km=km, **kwargs).execute()
           ^^^^^^^^^^^^^^^^^^^^^^^^^^^^^^^^^^^^^^^^^^^^^^^^^^^^^^^^^^^^^^^^^^^^^
  File "/home/auralius/miniconda3/envs/py.3.12.4/lib/python3.12/site-packages/jupyter_core/utils/__init__.py", line 165, in wrapped
    return loop.run_until_complete(inner)
           ^^^^^^^^^^^^^^^^^^^^^^^^^^^^^^
  File "/home/auralius/miniconda3/envs/py.3.12.4/lib/python3.12/asyncio/base_events.py", line 687, in run_until_complete
    return future.result()
           ^^^^^^^^^^^^^^^
  File "/home/auralius/miniconda3/envs/py.3.12.4/lib/python3.12/site-packages/nbclient/client.py", line 709, in async_execute
    await self.async_execute_cell(
  File "/home/auralius/miniconda3/envs/py.3.12.4/lib/python3.12/site-packages/nbclient/client.py", line 1062, in async_execute_cell
    await self._check_raise_for_error(cell, cell_index, exec_reply)
  File "/home/auralius/miniconda3/envs/py.3.12.4/lib/python3.12/site-packages/nbclient/client.py", line 918, in _check_raise_for_error
    raise CellExecutionError.from_cell_and_msg(cell, exec_reply_content)
nbclient.exceptions.CellExecutionError: An error occurred while executing the following cell:
------------------
import os

f1 = "./X_train_conv.txt"
f2 = "./X_test_conv.txt"

if os.path.exists(f1):
    os.remove(f1)

if os.path.exists(f2):
    os.remove(f2)

with open(f1, "ab") as f:
    for x in X_train_paded:
        img_out = convolve_image(x.reshape(16,16), [2,2], 2)
        #img_out = convolve_flattened_image(x.flatten(), 18, 18, [2,2], 2)
        np.savetxt(f, img_out.reshape(1,-1), fmt="%i", delimiter=',', newline='\n')

with open(f2, "ab") as f:
    for x in X_test_padded:
        img_out = convolve_image(x.reshape(16,16), [2,2], 2)
        #img_out = convolve_flattened_image(x.flatten(), 18, 18, [2,2], 2)
        np.savetxt(f, img_out.reshape(1,-1), fmt="%i", delimiter=',', newline='\n')
------------------


[0;31m---------------------------------------------------------------------------[0m
[0;31mValueError[0m                                Traceback (most recent call last)
Cell [0;32mIn[6], line 14[0m
[1;32m     12[0m [38;5;28;01mwith[39;00m [38;5;28mopen[39m(f1, [38;5;124m"[39m[38;5;124mab[39m[38;5;124m"[39m) [38;5;28;01mas[39;00m f:
[1;32m     13[0m     [38;5;28;01mfor[39;00m x [38;5;129;01min[39;00m X_train_paded:
[0;32m---> 14[0m         img_out [38;5;241m=[39m convolve_image([43mx[49m[38;5;241;43m.[39;49m[43mreshape[49m[43m([49m[38;5;241;43m16[39;49m[43m,[49m[38;5;241;43m16[39;49m[43m)[49m, [[38;5;241m2[39m,[38;5;241m2[39m], [38;5;241m2[39m)
[1;32m     15[0m         [38;5;66;03m#img_out = convolve_flattened_image(x.flatten(), 18, 18, [2,2], 2)[39;00m
[1;32m     16[0m         np[38;5;241m.[39msavetxt(f, img_out[38;5;241m.[39mreshape([38;5;241m1[39m,[38;5;241m-[39m[38;5;241m1[39m), fmt[38;5;241m=[39m[38;5;124m"[39m[38;5;132;01m%i[39;00m[38;5;124m"[39m, delimiter[38;5;241m=[39m[38;5;124m'[39m[38;5;124m,[39m[38;5;124m'[39m, newline[38;5;241m=[39m[38;5;124m'[39m[38;5;130;01m\n[39;00m[38;5;124m'[39m)

[0;31mValueError[0m: cannot reshape array of size 324 into shape (16,16)

